Workbook

Sheet ✅ TO DO
A1: STATUS | B1: TYPE | C1: TASK | D1: NOTES
A2: TRUE | B2: Structure | C2: Structure as a database | D2: Identify user entries vs automatic (fetch standard list, formula, call api)
A3: TRUE | B3: Structure | C3: Merge two tables diag_dpt et diag_process | D3: For each process, 1st step is "Global Assessment" > analyzed if details not filled
A4: TRUE | B4: Structure | C4: Merge two table lib_*
A5: TRUE | B5: Specification | C5: Workflow | D5: nb: "diag process" in several screens
A6: TRUE | B6: Specification | C6: UI | D6: None in v1 except "create mission" (copy lib_* data) and ai generated report
A7: TRUE | B7: Specification | C7: Review synergies "C@P" | D7: Former project (automatic consulting)
A8: FALSE | B8: Specification | C8: Audit Specif vs gSheet structure following tabs merger (_lib* and some 3_diag_*). Specs are: aiStrategy- specification | D8: CONTEXT: merger of some tabs in the Google Sheets (_lib_*, 3_diag_department into 3_diag_process). --- TASK: Audit carefully the discrepancies between the specificationi and the Google Sheet (SSOT). Note that this implies also some columns per sheet. --- OUTPUT: **Reference:** section/sub-section/header - Discrepancy: - Copy-paste ready Fix:
A9: FALSE | B9: Structure | C9: Add "AI analysis" columns per entry | D9: AI#1: enhance each entry in sheet; AI#2: generate global report /mission
A10: FALSE | B10: Structure | C10: Review all formulas | D10: nb: not too much since will be removed in v2 with a real database
A11: FALSE | B11: Content | C11: Finalize "library" sheets | D11: '- Merge "strat" questions with strateg- Change impact analytic framework - "_lib_strategy", "_lib_process" used as reference > loaded per user selection

Sheet 🚧 User_Guide
A1: # PROJECT PRESENTATION
A3: Specification | B3: https://docs.google.com/document/d/1U84ahHScW5QYnLXIggvfyfQVDUaEbbAiGZNCTcqcuQs/edit?usp=sharing
A5: ## EXEC. SUMMARY
A7: **Self-assessment tool** for SMBs to evaluate: - Strategic risk — Is AI an existential threat to the business model? - Process AI-eligibility — Which processes can realistically benefit from AI (value vs. feasibility)?
A9: **Output:** - A scored diagnosis - + AI-generated strategic report (Google Doc).
A11: **Core logic:** 1_company → 2_mission → 2_mission_function → optional instance creation in 3_diag_strategy and/or 3_diag_department + 3_diag_process → detailed scoring is entered at process level in 3_diag_process and/or manually at department level in 3_diag_department → formulas synthesize department-level outputs in 3_diag_department → final report generation tracked in 4_mission_report.
A13: **Structural principle:** - 2_mission = mission header only - 2_mission_function = authoritative function scope per mission - 3_diag_strategy = macro strategic diagnosis - 3_diag_department = function-scoped diagnosis + synthesis hub - 3_diag_process = function-scoped detailed scoring engine
A15: **Key implementation constraints:** - **Diagnosis instance creation must iterate from 2_mission_function:** Function scope is part of the primary grain and must never be inferred from labels, merged text, or department/process names. - **The scoring structure is a hard dependency:** crit_01…crit_14 in diagnosis tables must stay perfectly aligned with _scoring_criteria logical order, otherwise formulas and recommendation logic will silently break.
A17: ## FUNCTIONAL USER FLOW
A19: Workflow title | B19: User goal | C19: User action | D19: User-visible result | E19: What the script does
A20: mission_initialization | B20: Prepare the diagnosis workspace for one mission | C20: In `2_mission`, user selects a mission and clicks the initialization button | D20: Ready-to-fill diagnosis structure for the selected mission | E20: Checks: mission is valid + required diagnosis types are activated; If Process diagnosis is activated: - Checks that at least one mission Function is in scope; - Creates all missing diagnosis rows for this mission
A21: mission_initialization | B21: Load strategy diagnosis | C21: No action | D21: Strategy diagnosis rows ready to complete | E21: If Strategy diagnosis is activated: imports the relevant strategy questions for the mission
A22: mission_initialization | B22: Load process diagnosis | C22: No action | D22: Department and Process diagnosis rows ready to complete | E22: If Process diagnosis is activated: - Reads the mission functions in scope - Creates the related department rows and process rows
A23: diagnosis_completion | B23: Complete the assessment | C23: User fills in diagnosis sheets | D23: Mission diagnosis is progressively completed | E23: Nothing -> user inputs
A24: mission_report | B24: Start report generation | C24: User clicks the report button | D24: Mission to report on chosen | E24: Opens a dialog and loads selectable companies, missions, and AI options
A25: mission_report | B25: Select the target mission | C25: In the dialog, user selects company, then mission, then AI option | D25: Report generation launched on the correct mission | E25: Filters available missions for the selected company and validates the final selection
A26: mission_report | B26: Validate the request | C26: User clicks `Produce Report` | D26: Report generation starts only if inputs are valid | E26: Checks that company, mission, AI settings, and output location are valid and consistent
A27: mission_report | B27: Gather mission data | C27: No action | D27: All relevant mission data prepared for reporting | E27: Collects the company context, mission data, strategy diagnosis, and process diagnosis linked to the selected mission
A28: mission_report | B28: Generate the report | C28: No action | D28: Report text produced automatically | E28: Sends the structured mission data to the selected AI configuration and receives the written report
A29: mission_report | B29: Deliver the final output | C29: No action | D29: Ready-to-open report document | E29: Creates a Google Doc, stores the report in the target folder, and returns the document link
A30: error_handling | B30: Stop cleanly if blocked | C30: User sees message only if an issue occurs | D30: Understanding of failures | E30: Stops the workflow on blocking issues, logs the technical error, and returns a short readable message

Sheet 1_company
A1: [UUID- PK] | B1: [text] | C1: [text] | D1: [datalist] | E1: [datalist] | F1: [text] | G1: [datalist] | H1: [datalist] | I1: [text] | J1: [AI call] | K1: [text] | L1: [date] | M1: [date]
A2: id_company | B2: company_name | C2: contact_email | D2: ='_options_list'!B5 -> country | E2: ='_options_list'!B6 -> sector | F2: sub_sector | G2: ='_options_list'!B7 -> offer_type | H2: ='_options_list'!B8 -> client_type | I2: company_description | J2: v2_web_search | K2: comments | L2: created_at | M2: modified_at
A3: comp_001 | B3: Michelin Experiences | C3: a@michelin.com | D3: France | E3: "Hospitality, Tourism & Leisure" | F3: Publishing | G3: Make product, Move / Sell product | H3: B2B, B2C | I3: Lifestyle & tourism guides

Sheet 2_mission
A1: [UUID- PK] | B1: [UUID- FK] | C1: [text] | D1: [text] | E1: [datalist] | F1: [datalist] | G1: [datalist] | H1: [datalist] | I1: [datalist] | J1: [datalist] | K1: [text] | L1: [datalist] | M1: [date] | N1: [date]
A2: id_mission | B2: ='1_company'!A$2 -> id_company | C2: mission_name | D2: description | E2: has_strategy_diag | F2: has_process_diag | G2: priority_strategy | H2: priority_revenue | I2: priority_cost | J2: priority_implementation | K2: comments | L2: status | M2: created_at | N2: modified_at
A3: mis_001 | B3: comp_001 | C3: AI Strategy 360 | E3: TRUE | F3: TRUE | G3: 1 | H3: 2 | I3: 3 | J3: 2 | L3: Initialized

Sheet 2_mission_function
A1: [UUID- PK] | B1: [UUID- FK] | C1: [datalist] | D1: [text] | E1: [datalist] | F1: [date] | G1: [date]
A2: id_mission_function | B2: ='2_mission'!A$2 -> id_mission | C2: scope_function | D2: comments | E2: status | F2: created_at | G2: modified_at
A3: mis_001_func_001 | B3: mis_001 | C3: Marketing
A4: mis_001_func_002 | B4: mis_001 | C4: Sales & Service

Sheet 3_diag_strategy
A1: [UUID- PK] | B1: [UUID- FK] | C1: [UUID- FK] | D1: [text] | E1: [text] | F1: [datalist] | G1: [datalist] | H1: [datalist] | I1: [datalist] | J1: [datalist] | K1: [text] | L1: [text] | M1: [datalist] | N1: [date] | O1: [date]
A2: id_diag_strategy | B2: ='2_mission'!A$2 -> id_mission | C2: ='🚧 _lib_strategy'!D$2 -> #REF! | D2: ='🚧 _lib_strategy'!B2 -> #REF! | E2: ='🚧 _lib_strategy'!E2 -> #REF! | F2: is_customized | G2: is_deleted | H2: ='🚧 _lib_strategy'!F2 -> #REF! | I2: response_score | J2: response_confidence | K2: response_evidence | L2: response_comments | M2: is_answered | N2: created_at | O2: modified_at
A3: mis_strat_001 | B3: mis_001 | C3: ='🚧 _lib_strategy'!D3 -> #REF! | D3: ='🚧 _lib_strategy'!B3 -> #REF! | E3: ='🚧 _lib_strategy'!E3 -> #REF! | F3: FALSE | G3: FALSE | H3: ='🚧 _lib_strategy'!F3 -> #REF! | I3: 3 | M3: TRUE
A4: mis_strat_002 | B4: mis_001 | C4: ='🚧 _lib_strategy'!D4 -> #REF! | D4: ='🚧 _lib_strategy'!B4 -> #REF! | E4: ='🚧 _lib_strategy'!E4 -> #REF! | F4: FALSE | G4: FALSE | H4: ='🚧 _lib_strategy'!F4 -> #REF! | I4: #NA | M4: FALSE
A5: mis_strat_003 | B5: mis_001 | C5: ='🚧 _lib_strategy'!D5 -> #REF! | D5: ='🚧 _lib_strategy'!B5 -> #REF! | E5: ='🚧 _lib_strategy'!E5 -> #REF! | F5: FALSE | G5: FALSE | H5: ='🚧 _lib_strategy'!F5 -> #REF! | M5: FALSE
A6: mis_strat_004 | B6: mis_001 | C6: ='🚧 _lib_strategy'!D6 -> #REF! | D6: ='🚧 _lib_strategy'!B6 -> #REF! | E6: ='🚧 _lib_strategy'!E6 -> #REF! | F6: FALSE | G6: FALSE | H6: ='🚧 _lib_strategy'!F6 -> #REF! | I6: 2 | M6: TRUE
A7: mis_strat_005 | B7: mis_001 | C7: ='🚧 _lib_strategy'!D7 -> #REF! | D7: ='🚧 _lib_strategy'!B7 -> #REF! | E7: ='🚧 _lib_strategy'!E7 -> #REF! | F7: FALSE | G7: FALSE | H7: ='🚧 _lib_strategy'!F7 -> #REF! | M7: FALSE
A8: mis_strat_006 | B8: mis_001 | C8: ='🚧 _lib_strategy'!D8 -> #REF! | D8: ='🚧 _lib_strategy'!B8 -> #REF! | E8: ='🚧 _lib_strategy'!E8 -> #REF! | F8: FALSE | G8: FALSE | H8: ='🚧 _lib_strategy'!F8 -> #REF! | M8: FALSE
A9: mis_strat_007 | B9: mis_001 | C9: ='🚧 _lib_strategy'!D9 -> #REF! | D9: ='🚧 _lib_strategy'!B9 -> #REF! | E9: ='🚧 _lib_strategy'!E9 -> #REF! | F9: FALSE | G9: FALSE | H9: ='🚧 _lib_strategy'!F9 -> #REF! | I9: #NA | M9: FALSE
A10: mis_strat_008 | B10: mis_001 | C10: ='🚧 _lib_strategy'!D10 -> #REF! | D10: ='🚧 _lib_strategy'!B10 -> #REF! | E10: ='🚧 _lib_strategy'!E10 -> #REF! | F10: FALSE | G10: FALSE | H10: ='🚧 _lib_strategy'!F10 -> #REF! | I10: #NA | M10: FALSE
A11: mis_strat_009 | B11: mis_001 | C11: ='🚧 _lib_strategy'!D11 -> #REF! | D11: ='🚧 _lib_strategy'!B11 -> #REF! | E11: ='🚧 _lib_strategy'!E11 -> #REF! | F11: FALSE | G11: FALSE | H11: ='🚧 _lib_strategy'!F11 -> #REF! | I11: #NA | M11: FALSE
A12: mis_strat_010 | B12: mis_001 | C12: ='🚧 _lib_strategy'!D12 -> #REF! | D12: ='🚧 _lib_strategy'!B12 -> #REF! | E12: ='🚧 _lib_strategy'!E12 -> #REF! | F12: FALSE | G12: FALSE | H12: ='🚧 _lib_strategy'!F12 -> #REF! | I12: #NA | M12: FALSE
A13: mis_strat_011 | B13: mis_001 | C13: ='🚧 _lib_strategy'!D13 -> #REF! | D13: ='🚧 _lib_strategy'!B13 -> #REF! | E13: ='🚧 _lib_strategy'!E13 -> #REF! | F13: FALSE | G13: FALSE | H13: ='🚧 _lib_strategy'!F13 -> #REF! | I13: #NA | M13: FALSE
A14: mis_strat_012 | B14: mis_001 | C14: ='🚧 _lib_strategy'!D14 -> #REF! | D14: ='🚧 _lib_strategy'!B14 -> #REF! | E14: ='🚧 _lib_strategy'!E14 -> #REF! | F14: FALSE | G14: FALSE | H14: ='🚧 _lib_strategy'!F14 -> #REF! | I14: #NA | M14: FALSE

Sheet 3_diag_process
A1: [UUID- PK] | B1: [formula] | C1: [formula] | D1: [UUID- FK] | E1: [UUID- FK] | F1: [text] | G1: [UUID- FK] | H1: [datalist] | I1: [datalist] | J1: [text] | K1: [datalist] | L1: [text] | M1: [text] | N1: [datalist] | O1: [text] | P1: =VLOOKUP(P$2,'_scoring_criteria'!$B$3:$D$16,3,false) -> (value) FTE intensive | Q1: =VLOOKUP(Q$2,'_scoring_criteria'!$B$3:$D$16,3,false) -> (value) Recurring | R1: =VLOOKUP(R$2,'_scoring_criteria'!$B$3:$D$16,3,false) -> (value) Misquality | S1: =VLOOKUP(S$2,'_scoring_criteria'!$B$3:$D$16,3,false) -> (feasib) Data collection | T1: =VLOOKUP(T$2,'_scoring_criteria'!$B$3:$D$16,3,false) -> (feasib) Analysis & Writing | U1: =VLOOKUP(U$2,'_scoring_criteria'!$B$3:$D$16,3,false) -> (feasib) Multimedia | V1: =VLOOKUP(V$2,'_scoring_criteria'!$B$3:$D$16,3,false) -> (feasib) Interaction | W1: =VLOOKUP(W$2,'_scoring_criteria'!$B$3:$D$16,3,false) -> (feasib) Human_specific | ... AC1: =VLOOKUP(AC$2,'_scoring_criteria'!$B$3:$D$16,3,false) -> (feasib) Fresh data | AD1: [formula] | AE1: [formula] | AF1: [formula] | AG1: [AI call] | AH1: [AI call] | AI1: [AI call] | AJ1: [AI call] | AK1: [AI call] | AL1: [datalist] | AM1: [date] | AN1: [date]
A2: =IFERROR(__xludf.DUMMYFUNCTION("{""id_diag_process"";ARRAYFORMULA(D3:D18&""_dpt_""&TEXT(FILTER(ROW(D2:D18)-1,D2:D18<>""""),""000""))}"),"id_diag_process") -> id_diag_process | B2: ='_lib_questions'!B2 -> id_question_lib | C2: ='_lib_questions'!J2 -> question_lib | D2: ='2_mission_function'!A2 -> id_mission_function | E2: ='_lib_questions'!D2 -> id_category_L1_lib | F2: title_cat_L1_lib | G2: ='🚧 _lib_process'!B2 -> #REF! | H2: is_customized | I2: is_deleted | J2: input_example | K2: operating_tool | L2: output_example | M2: yearly_volume_indicator | N2: sensitivity | O2: comments | P2: {=transpose(unique('_scoring_criteria'!B$3:B18))} -> crit_01 | Q2: crit_02 | R2: crit_03 | S2: crit_04 | T2: crit_05 | U2: crit_06 | V2: crit_07 | W2: crit_08 | X2: crit_09 | Y2: crit_10 | Z2: crit_11 | AA2: crit_12 | AB2: crit_13 | AC2: crit_14 | AD2: {={"asst_VALUE"; IF(P3:P18="", "", IFERROR( BYROW(P3:R18, LAMBDA(r, SUMPRODUCT( IF(ISNUMBER(r),r,0), XLOOKUP(P$2:R$2,#REF!,#REF!), XLOOKUP(P$2:R$2,#REF!,#REF!) ) / SUMPRODUCT( --ISNUMBER(r), ABS( XLOOKUP(P$2:R$2,#REF!,#REF!)* XLOOKUP(P$2:R$2,#REF!,#REF!) ) ) )), "" ) )}} -> asst_VALUE | AE2: {={"asst_FEASIBILITY"; IF(S3:S18="", "", IFERROR( BYROW(S3:AC18, LAMBDA(r, SUMPRODUCT( IF(ISNUMBER(r),r,0), XLOOKUP(S$2:AC$2,#REF!,#REF!), XLOOKUP(S$2:AC$2,#REF!,#REF!) ) / SUMPRODUCT( --ISNUMBER(r), ABS( XLOOKUP(S$2:AC$2,#REF!,#REF!)* XLOOKUP(S$2:AC$2,#REF!,#REF!) ) ) )), "" ) )}} -> asst_FEASIBILITY | AF2: {={"(mAcro_asst) RECO";IF((AD3:AD100="")+(AE3:AE100=""),,"Prio "&RANK((AD3:AD100+AE3:AE100)/2,(AD3:AD100+AE3:AE100)/2,0))}} -> (mAcro_asst) RECO | AG2: reco_WHY | AH2: reco_RISK | AI2: reco_TOOL | AJ2: reco_NEXT | AK2: reco_EFFORT | AL2: is_answered | AM2: created_at | AN2: modified_at
A3: =IFERROR(__xludf.DUMMYFUNCTION("""COMPUTED_VALUE"""),"mis_001_func_001_dpt_001") -> mis_001_func_001_dpt_001 | D3: mis_001_func_001 | F3: Sales & Service | G3: =vlookup(#REF!,#REF!,3,false) -> #REF! | H3: FALSE | I3: FALSE | J3: Strat. objective, budget; Market research | K3: Bureautic soft, Web Data search | L3: Plan (sectors/companies, budget/proba, Resp...) | M3: 4 sessions /year | N3: 1 | P3: 1 | Q3: 1 | R3: 1 | S3: 3 | T3: 2 | U3: 2 | V3: 1 | W3: 3 | X3: 2 | Y3: 3 | Z3: 1 | AA3: 1 | AB3: 3 | AC3: 2 | AG3: [AI analysis getting the overall input from each sheet] | AH3: [AI analysis getting the overall input from each sheet] | AI3: [AI analysis getting the overall input from each sheet] | AJ3: [AI analysis getting the overall input from each sheet] | AK3: [AI analysis getting the overall input from each sheet] | AL3: TRUE
A4: =IFERROR(__xludf.DUMMYFUNCTION("""COMPUTED_VALUE"""),"mis_001_func_001_dpt_002") -> mis_001_func_001_dpt_002 | D4: mis_001_func_001 | F4: Sales & Service | G4: =vlookup(#REF!,#REF!,3,false) -> #REF! | H4: FALSE | I4: FALSE | K4: Bureautic soft, eMail / Instant messenger, Web Data search, Meeting / Phone call | M4: 200 sessions /year | P4: 3 | Q4: 2 | R4: 3 | S4: 2 | T4: 1 | U4: 3 | V4: 2 | W4: 1 | X4: 3 | Y4: 3 | Z4: 2 | AA4: 3 | AB4: 1 | AC4: 2 | AL4: TRUE
A5: =IFERROR(__xludf.DUMMYFUNCTION("""COMPUTED_VALUE"""),"mis_001_func_001_dpt_003") -> mis_001_func_001_dpt_003 | D5: mis_001_func_001 | F5: Sales & Service | G5: =vlookup(#REF!,#REF!,3,false) -> #REF! | H5: FALSE | I5: FALSE | P5: 2 | Q5: 3 | R5: 2 | S5: 3 | T5: 3 | U5: 3 | V5: 3 | W5: 2 | X5: 2 | Y5: 3 | Z5: 1 | AA5: 3 | AB5: 0 | AC5: 0 | AL5: TRUE
A6: =IFERROR(__xludf.DUMMYFUNCTION("""COMPUTED_VALUE"""),"mis_001_func_001_dpt_004") -> mis_001_func_001_dpt_004 | D6: mis_001_func_001 | F6: Sales & Service | G6: =vlookup(#REF!,#REF!,3,false) -> #REF! | H6: FALSE | I6: FALSE | P6: 1 | Q6: 0 | R6: 0 | S6: 0 | T6: 0 | U6: 0 | V6: 0 | W6: 0 | X6: 0 | Y6: 0 | Z6: 0 | AA6: 0 | AB6: 0 | AC6: 0 | AL6: TRUE
A7: =IFERROR(__xludf.DUMMYFUNCTION("""COMPUTED_VALUE"""),"mis_001_func_001_dpt_005") -> mis_001_func_001_dpt_005 | D7: mis_001_func_001 | F7: Sales & Service | G7: =vlookup(#REF!,#REF!,3,false) -> #REF! | H7: FALSE | I7: FALSE | P7: 3 | Q7: 0 | R7: 0 | S7: 0 | T7: 0 | U7: 0 | V7: 0 | W7: 0 | X7: 0 | Y7: 0 | Z7: 0 | AA7: 0 | AB7: 0 | AC7: 0 | AL7: TRUE
A8: =IFERROR(__xludf.DUMMYFUNCTION("""COMPUTED_VALUE"""),"mis_001_func_001_dpt_006") -> mis_001_func_001_dpt_006 | D8: mis_001_func_001 | F8: Sales & Service | G8: =vlookup(#REF!,#REF!,3,false) -> #REF! | H8: FALSE | I8: FALSE | P8: 2 | Q8: 0 | R8: 0 | S8: 0 | T8: 0 | U8: 0 | V8: 0 | W8: 0 | X8: 0 | Y8: 0 | Z8: 0 | AA8: 0 | AB8: 0 | AC8: 0 | AL8: TRUE
A9: =IFERROR(__xludf.DUMMYFUNCTION("""COMPUTED_VALUE"""),"mis_001_func_001_dpt_007") -> mis_001_func_001_dpt_007 | D9: mis_001_func_001 | F9: Sales & Service | G9: =vlookup(#REF!,#REF!,3,false) -> #REF! | H9: FALSE | I9: FALSE | P9: 0 | Q9: 0 | R9: 0 | S9: 0 | T9: 0 | U9: 0 | V9: 0 | W9: 0 | X9: 0 | Y9: 0 | Z9: 0 | AA9: 0 | AB9: 0 | AC9: 0 | AL9: FALSE
A10: =IFERROR(__xludf.DUMMYFUNCTION("""COMPUTED_VALUE"""),"mis_001_func_001_dpt_008") -> mis_001_func_001_dpt_008 | D10: mis_001_func_001 | F10: Sales & Service | G10: =vlookup(#REF!,#REF!,3,false) -> #REF! | H10: FALSE | I10: FALSE | P10: 0 | Q10: 0 | R10: 0 | S10: 0 | T10: 0 | U10: 0 | V10: 0 | W10: 0 | X10: 0 | Y10: 0 | Z10: 0 | AA10: 0 | AB10: 0 | AC10: 0 | AL10: FALSE
A11: =IFERROR(__xludf.DUMMYFUNCTION("""COMPUTED_VALUE"""),"mis_001_func_001_dpt_009") -> mis_001_func_001_dpt_009 | D11: mis_001_func_001 | F11: Sales & Service | G11: =vlookup(#REF!,#REF!,3,false) -> #REF! | H11: FALSE | I11: FALSE | P11: 0 | Q11: 0 | R11: 0 | S11: 0 | T11: 0 | U11: 0 | V11: 0 | W11: 0 | X11: 0 | Y11: 0 | Z11: 0 | AA11: 0 | AB11: 0 | AC11: 0 | AL11: FALSE
A12: =IFERROR(__xludf.DUMMYFUNCTION("""COMPUTED_VALUE"""),"mis_001_func_001_dpt_010") -> mis_001_func_001_dpt_010 | D12: mis_001_func_001 | F12: Sales & Service | G12: =vlookup(#REF!,#REF!,3,false) -> #REF! | H12: FALSE | I12: FALSE | P12: 0 | Q12: 0 | R12: 0 | S12: 0 | T12: 0 | U12: 0 | V12: 0 | W12: 0 | X12: 0 | Y12: 0 | Z12: 0 | AA12: 0 | AB12: 0 | AC12: 0 | AL12: FALSE
A13: =IFERROR(__xludf.DUMMYFUNCTION("""COMPUTED_VALUE"""),"mis_001_func_001_dpt_011") -> mis_001_func_001_dpt_011 | D13: mis_001_func_001 | F13: Sales & Service | G13: =vlookup(#REF!,#REF!,3,false) -> #REF! | H13: FALSE | I13: FALSE | P13: 0 | Q13: 0 | R13: 0 | S13: 0 | T13: 0 | U13: 0 | V13: 0 | W13: 0 | X13: 0 | Y13: 0 | Z13: 0 | AA13: 0 | AB13: 0 | AC13: 0 | AL13: FALSE
A14: =IFERROR(__xludf.DUMMYFUNCTION("""COMPUTED_VALUE"""),"mis_001_func_001_dpt_012") -> mis_001_func_001_dpt_012 | D14: mis_001_func_001 | F14: Sales & Service | G14: =vlookup(#REF!,#REF!,3,false) -> #REF! | H14: FALSE | I14: FALSE | P14: 0 | Q14: 0 | R14: 0 | S14: 0 | T14: 0 | U14: 0 | V14: 0 | W14: 0 | X14: 0 | Y14: 0 | Z14: 0 | AA14: 0 | AB14: 0 | AC14: 0 | AL14: FALSE
A15: =IFERROR(__xludf.DUMMYFUNCTION("""COMPUTED_VALUE"""),"mis_001_func_001_dpt_013") -> mis_001_func_001_dpt_013 | D15: mis_001_func_001 | F15: Sales & Service | G15: =vlookup(#REF!,#REF!,3,false) -> #REF! | H15: FALSE | I15: FALSE | P15: 0 | Q15: 0 | R15: 0 | S15: 0 | T15: 0 | U15: 0 | V15: 0 | W15: 0 | X15: 0 | Y15: 0 | Z15: 0 | AA15: 0 | AB15: 0 | AC15: 0
A16: =IFERROR(__xludf.DUMMYFUNCTION("""COMPUTED_VALUE"""),"mis_001_func_001_dpt_014") -> mis_001_func_001_dpt_014 | D16: mis_001_func_001 | F16: Sales & Service | G16: =vlookup(#REF!,#REF!,3,false) -> #REF! | H16: FALSE | I16: FALSE | P16: 0 | Q16: 0 | R16: 0 | S16: 0 | T16: 0 | U16: 0 | V16: 0 | W16: 0 | X16: 0 | Y16: 0 | Z16: 0 | AA16: 0 | AB16: 0 | AC16: 0
A17: =IFERROR(__xludf.DUMMYFUNCTION("""COMPUTED_VALUE"""),"_dpt_015") -> _dpt_015
A18: =IFERROR(__xludf.DUMMYFUNCTION("""COMPUTED_VALUE"""),"#N/A") -> #N/A

Sheet 4_mission_report
A1: [UUID- PK] | B1: [number] | C1: [UUID- FK] | D1: [UUID- FK] | E1: [UUID- FK] | F1: [datalist] | G1: [text] | H1: [datalist] | I1: [date] | J1: [date]
A2: id_report | B2: version_report | C2: ='2_mission'!A2 -> id_mission | D2: ='_settings_outputs'!A2 -> id_output_config | E2: ='_settings_api'!A2 -> api_id | F2: output_type | G2: output_url | H2: status | I2: created_at | J2: modified_at

Sheet _lib_mission_type
A1: [datalist] | B1: [UUID- PK] | C1: [text] | D1: [date] | E1: [date]
A2: is_active | B2: id_mission_type_lib | C2: title_mission_type_lib | D2: created_at | E2: modified_at
A3: TRUE | B3: strat_01 | C3: Strategy AI
A4: TRUE | B4: proc_01 | C4: Process AI

Sheet _lib_cat_L1
A1: [datalist] | B1: [UUID- FK] | C1: [gSheet-only helper] | D1: [UUID- PK] | E1: [text] | F1: [date] | G1: [date]
A2: is_active | B2: {={'_lib_mission_type'!B$2; IF(C3:C17="", , XLOOKUP(C3:C17, '_lib_mission_type'!C3:C17, '_lib_mission_type'!B3:B17, ""))}} -> id_mission_type_lib | C2: ='_lib_mission_type'!C$2 -> title_mission_type_lib | D2: {={"id_cat_L1_lib";IF(C3:C17="",,xlookup(C3:C17,'_lib_mission_type'!C2:C17,'_lib_mission_type'!B2:B17)&"_"&TEXT(COUNTIFS(C$3:C17,C3:C17,ROW(C$3:C17),"<="&ROW(C3:C17)),"00"))}} -> id_cat_L1_lib | E2: title_cat_L1_lib | F2: created_at | G2: modified_at
A3: TRUE | B3: strat_01 | C3: Strategy AI | D3: strat_01_01 | E3: Reality check
A4: TRUE | B4: strat_01 | C4: Strategy AI | D4: strat_01_02 | E4: Materiality
A5: TRUE | B5: strat_01 | C5: Strategy AI | D5: strat_01_03 | E5: Market impact
A6: TRUE | B6: strat_01 | C6: Strategy AI | D6: strat_01_04 | E6: Internal impact
A7: TRUE | B7: strat_01 | C7: Strategy AI | D7: strat_01_05 | E7: Execution
A8: FALSE | B8: proc_01 | C8: Process AI | D8: proc_01_01 | E8: Strategy
A9: FALSE | B9: proc_01 | C9: Process AI | D9: proc_01_02 | E9: R&D
A10: FALSE | B10: proc_01 | C10: Process AI | D10: proc_01_03 | E10: Marketing
A11: TRUE | B11: proc_01 | C11: Process AI | D11: proc_01_04 | E11: Sales & Service
A12: FALSE | B12: proc_01 | C12: Process AI | D12: proc_01_05 | E12: Operations
A13: FALSE | B13: proc_01 | C13: Process AI | D13: proc_01_06 | E13: Finance
A14: FALSE | B14: proc_01 | C14: Process AI | D14: proc_01_07 | E14: HR
... A17: FALSE | B17: proc_01 | C17: Process AI | D17: proc_01_10 | E17: Communication

Sheet _lib_cat_L2
A1: [datalist] | B1: [UUID- FK] | C1: [gSheet-only helper] | D1: [UUID- FK] | E1: [gSheet-only helper] | F1: [UUID- PK] | G1: [text] | H1: [date] | I1: [date]
A2: is_active | B2: {={'_lib_mission_type'!B$2; IF(C3:C113="", , XLOOKUP(C3:C113, '_lib_mission_type'!C3:C113, '_lib_mission_type'!B3:B113, ""))}} -> id_mission_type_lib | C2: ='_lib_mission_type'!C2 -> title_mission_type_lib | D2: {={'_lib_cat_L1'!D$2; IF(E3:E113="", , XLOOKUP(E3:E113, '_lib_cat_L1'!E3:E113, '_lib_cat_L1'!D3:D113, ""))}} -> id_cat_L1_lib | E2: ='_lib_cat_L1'!E2 -> title_cat_L1_lib | F2: {={"id_cat_L2_lib"; IF(D3:D113="",, D3:D113&"_"&TEXT(COUNTIFS(D$3:D113,D3:D113,ROW(D$3:D113),"<="&ROW(D3:D113)),"00"))}} -> id_cat_L2_lib | G2: title_cat_L2_lib | H2: created_at | I2: modified_at
A3: TRUE | B3: strat_01 | C3: Strategy AI | D3: strat_01_01 | E3: Reality check | F3: strat_01_01_01 | G3: Enjeu stratégique de l'IA
A4: TRUE | B4: strat_01 | C4: Strategy AI | D4: strat_01_05 | E4: Execution | F4: strat_01_05_01 | G4: Alignement avec les priorités
A5: TRUE | B5: strat_01 | C5: Strategy AI | D5: strat_01_04 | E5: Internal impact | F5: strat_01_04_01 | G5: Identification des cas d’usage
A6: TRUE | B6: strat_01 | C6: Strategy AI | D6: strat_01_05 | E6: Execution | F6: strat_01_05_02 | G6: Maturité data & technologique
A7: TRUE | B7: strat_01 | C7: Strategy AI | D7: strat_01_05 | E7: Execution | F7: strat_01_05_03 | G7: Modèle opérationnel IA
A8: TRUE | B8: strat_01 | C8: Strategy AI | D8: strat_01_04 | E8: Internal impact | F8: strat_01_04_02 | G8: Roadmap & priorisation
A9: TRUE | B9: strat_01 | C9: Strategy AI | D9: strat_01_05 | E9: Execution | F9: strat_01_05_04 | G9: Gouvernance & risques
A10: TRUE | B10: strat_01 | C10: Strategy AI | D10: strat_01_05 | E10: Execution | F10: strat_01_05_05 | G10: Conduite du changement
A11: TRUE | B11: proc_01 | C11: Process AI | D11: proc_01_04 | E11: Sales & Service | F11: proc_01_04_01 | G11: Sales Planning
A12: TRUE | B12: proc_01 | C12: Process AI | D12: proc_01_04 | E12: Sales & Service | F12: proc_01_04_02 | G12: Business Development & Lead Generation
A13: TRUE | B13: proc_01 | C13: Process AI | D13: proc_01_04 | E13: Sales & Service | F13: proc_01_04_03 | G13: Outbound Prospecting
A14: TRUE | B14: proc_01 | C14: Process AI | D14: proc_01_04 | E14: Sales & Service | F14: proc_01_04_04 | G14: Inbound Lead Management
... A24: TRUE | B24: proc_01 | C24: Process AI | D24: proc_01_04 | E24: Sales & Service | F24: proc_01_04_14 | G24: Voice of Customer & Continuous Improvement
A25: FALSE | B25: proc_01 | C25: Process AI | G25: Business Planning
A26: FALSE | B26: proc_01 | C26: Process AI | G26: Market Analysis
A27: FALSE | B27: proc_01 | C27: Process AI | G27: Idea generation
A28: FALSE | B28: proc_01 | C28: Process AI | G28: Innovation Management
A29: FALSE | B29: proc_01 | C29: Process AI | G29: Intellectual property management
A30: FALSE | B30: proc_01 | C30: Process AI | G30: Prototyping
A31: FALSE | B31: proc_01 | C31: Process AI | G31: Research
A32: FALSE | B32: proc_01 | C32: Process AI | G32: Research and Development
A33: FALSE | B33: proc_01 | C33: Process AI | G33: Technology transfer
A34: FALSE | B34: proc_01 | C34: Process AI | G34: STRATÉGIE
A35: FALSE | B35: proc_01 | C35: Process AI | G35: Advertising & SEO/SEA
A36: FALSE | B36: proc_01 | C36: Process AI | G36: Affiliates & Influencers Partnerships
... A113: FALSE | B113: proc_01 | C113: Process AI | G113: Public Relations

Sheet _lib_questions
A1: [datalist] | B1: [UUID- PK] | C1: [datalist] | D1: [text] | E1: [text] | F1: [text] | G1: [text] | H1: [text] | I1: [text] | J1: [text] | K1: [text] | M1: [datalist] | N1: [datalist] | O1: [text] | P1: [date] | Q1: [date]
A2: is_active | B2: id_question_lib | C2: id_domain_lib | D2: id_category_L1_lib | E2: title_category_L1_lib | F2: id_category_L2_lib | G2: title_category_L2_lib | H2: id_category_L3_lib | I2: title_category_L3_lib | J2: question_lib | K2: question_description_lib | L2: response_is_global | M2: response_type | N2: prompt_type_lib | O2: prompt_lib | P2: created_at | Q2: modified_at
A3: TRUE | C3: Strategy | E3: sqdf | G3: 0. Enjeu stratégique de l'IA | J3: GLOBAL CATEGORY ASST | L3: YES | M3: 3 to 0
A4: TRUE | C4: Strategy | E4: sqdf | G4: 0. Enjeu stratégique de l'IA | J4: Des acteurs natifs IA peuvent-ils offrir notre service à coût marginal proche de zéro ? | M4: 3 to 0
A5: TRUE | C5: Strategy | E5: sqdf | G5: 0. Enjeu stratégique de l'IA | J5: L’IA modifie-t-elle les barrières à l’entrée ou la chaîne de valeur ? | M5: 3 to 0
A6: TRUE | C6: Strategy | E6: sqdf | G6: 0. Enjeu stratégique de l'IA | J6: Notre cœur de valeur est-il basé sur l’analyse, la prévision ou l’expertise cognitive ? | M6: 3 to 0
A7: TRUE | C7: Strategy | E7: sqdf | G7: 0. Enjeu stratégique de l'IA | J7: Notre proposition de valeur devient-elle automatisable ou commoditisée ? | M7: 3 to 0
A8: TRUE | C8: Strategy | E8: sqdf | G8: 0. Enjeu stratégique de l'IA | J8: Un nouveau modèle économique est-il possible (plateforme, outcome-based pricing, data-as-a-service) | M8: 3 to 0
A9: FALSE | C9: Strategy | E9: sqdf | G9: 0. Enjeu stratégique de l'IA | J9: La donnée peut-elle devenir un actif stratégique monétisable ? | M9: 3 to 0
G10: 1. Alignement avec les priorités | J10: GLOBAL CATEGORY ASST | L10: YES | M10: 3 to 0
A11: FALSE | C11: Strategy | E11: sqdf | J11: Quelles sont nos 3–5 priorités stratégiques à 3 ans ? | M11: Text
A12: FALSE | C12: Strategy | E12: sqdf | G12: 1. Alignement avec les priorités | J12: Où sont nos principaux goulets d’étranglement ? | M12: Text
A13: FALSE | C13: Strategy | E13: sqdf | G13: 1. Alignement avec les priorités | J13: Quelles décisions critiques reposent sur des données mal exploitées ? | M13: Text
A14: FALSE | C14: Strategy | E14: sqdf | G14: 1. Alignement avec les priorités | J14: Cherchons-nous optimisation incrémentale, différenciation ou transformation ? | M14: Text
G15: 2. Identification des cas d’usage | J15: GLOBAL CATEGORY ASST | L15: YES | M15: 3 to 0
A16: FALSE | C16: Strategy | E16: sqdf | J16: Où l’IA peut-elle augmenter le revenu ? | M16: Text
A17: FALSE | C17: Strategy | E17: sqdf | G17: 2. Identification des cas d’usage | J17: Où l’IA peut-elle réduire les coûts ? | M17: Text
A18: FALSE | C18: Strategy | E18: sqdf | G18: 2. Identification des cas d’usage | J18: Où l’IA peut-elle réduire le risque ? | M18: Text
A19: FALSE | C19: Strategy | E19: sqdf | G19: 2. Identification des cas d’usage | J19: Les données nécessaires sont-elles disponibles et exploitables ? | M19: 3 to 0
A20: FALSE | C20: Strategy | E20: sqdf | G20: 2. Identification des cas d’usage | J20: Le ROI est-il mesurable à court ou moyen terme ? | M20: 3 to 0
G21: 3. Maturité data & technologique | J21: GLOBAL CATEGORY ASST | L21: YES | M21: 3 to 0
A22: FALSE | C22: Strategy | E22: sqdf | G22: 3. Maturité data & technologique | J22: Les données sont-elles centralisées et de qualité suffisante ? | M22: 3 to 0
A23: FALSE | C23: Strategy | G23: 3. Maturité data & technologique | J23: L’infrastructure (cloud, APIs, outils ML) est-elle prête ? | M23: 3 to 0
A24: FALSE | C24: Strategy | G24: 3. Maturité data & technologique | J24: Avons-nous les talents nécessaires (data engineers, data scientists, product owners IA) ? | M24: 3 to 0
A25: FALSE | C25: Strategy | G25: 3. Maturité data & technologique | J25: La gouvernance data est-elle claire et conforme (RGPD, sécurité) ? | M25: 3 to 0
G26: 4. Modèle opérationnel IA | J26: GLOBAL CATEGORY ASST | L26: YES | M26: 3 to 0
A27: FALSE | C27: Strategy | G27: 4. Modèle opérationnel IA | J27: Y-a-t-il un responsable du ROI des cas d’usage ? | M27: 3 to 0
A28: FALSE | C28: Strategy | G28: 4. Modèle opérationnel IA | J28: Faut-il un centre d’excellence IA ou un modèle hybride ? | M28: Text
A29: FALSE | C29: Strategy | G29: 4. Modèle opérationnel IA | J29: Y-a-t-il un responsable de la maintenance et la surveillance des modèles en production ? | M29: 3 to 0
A30: FALSE | C30: Strategy | G30: 4. Modèle opérationnel IA | J30: Build, buy ou partenariat ? | M30: Text
G31: 5. Roadmap & priorisation | J31: GLOBAL CATEGORY ASST | L31: YES | M31: 3 to 0
A32: FALSE | C32: Strategy | G32: 5. Roadmap & priorisation | J32: Y-a-t-il des quick wins lançables sous 3 mois ? | M32: 3 to 0
A33: FALSE | C33: Strategy | G33: 5. Roadmap & priorisation | J33: Quels prérequis data sont critiques ? | M33: Text
A34: FALSE | C34: Strategy | G34: 5. Roadmap & priorisation | J34: Quel budget et quels indicateurs de succès ? | M34: Text
G35: 6. Gouvernance & risques | J35: GLOBAL CATEGORY ASST
A36: FALSE | C36: Strategy | E36: Exécution | G36: 6. Gouvernance & risques | J36: Existe-t-il un comité IA formel ? | M36: 3 to 0
A37: FALSE | C37: Strategy | E37: Exécution | G37: 6. Gouvernance & risques | J37: Comment prévenir les biais et assurer l’auditabilité ? | M37: Text
A38: FALSE | C38: Strategy | E38: Exécution | G38: 6. Gouvernance & risques | J38: La cybersécurité est-elle adaptée aux usages IA ? | M38: 3 to 0
G39: 7. Conduite du changement | J39: GLOBAL CATEGORY ASST | L39: YES | M39: 3 to 0
A40: FALSE | C40: Strategy | E40: Exécution | G40: 7. Conduite du changement | J40: Les équipes comprennent-elles les enjeux IA ? | M40: 3 to 0
...

Sheet _scoring_criteria
A1: [datalist] | B1: [UUID- PK] | C1: [text] | D1: [text] | E1: [text] | F1: [datalist] | G1: [datalist] | H1: [formula] | I1: [date] | J1: [date]
A2: ='_lib_questions'!C2 -> id_domain_lib | B2: id_criteria | C2: type_criteria | D2: title_criteria | E2: description_criteria | F2: importance | G2: fosters_ai | H2: score_ai | I2: created_at | J2: modified_at
A3: Process | B3: crit_01 | C3: value | D3: (value) FTE intensive | E3: Many people in the process / Variable with activity | F3: 3 | G3: 1 | H3: =average(F3:G3) -> 2
A4: Process | B4: crit_02 | C4: =C3 -> value | D4: (value) Recurring | E4: Process frequency | F4: 3 | G4: 1 | H4: =average(F4:G4) -> 2
A5: Process | B5: crit_03 | C5: =C4 -> value | D5: (value) Misquality | E5: Many errors in the process | F5: 2 | G5: 1 | H5: =average(F5:G5) -> 1.5
A6: Process | B6: crit_04 | C6: activity_type | D6: (feasib) Data collection | E6: crawl, query IS, contact stakeholders | F6: 3 | G6: 1 | H6: =average(F6:G6) -> 2
A7: Process | B7: crit_05 | C7: =C6 -> activity_type | D7: (feasib) Analysis & Writing | E7: calculating/summarising, textual production | F7: 2 | G7: 1 | H7: =average(F7:G7) -> 1.5
A8: Process | B8: crit_06 | C8: =C6 -> activity_type | D8: (feasib) Multimedia | E8: creation of images / videos / audio | F8: 2 | G8: 1 | H8: =average(F8:G8) -> 1.5
A9: Process | B9: crit_07 | C9: =C6 -> activity_type | D9: (feasib) Interaction | E9: discussion, orchestration tasks, multiple stakeholders | F9: 2 | G9: 1 | H9: =average(F9:G9) -> 1.5
A10: Process | B10: crit_08 | C10: skill | D10: (feasib) Human_specific | E10: requires intuition, craft, adaptability + manual gesture | F10: 2 | G10: -1 | H10: =average(F10:G10) -> 0.5
A11: Process | B11: crit_09 | C11: =C10 -> skill | D11: (feasib) Business_specific | E11: strong business-specific/contextual knowledge | F11: 3 | G11: -1 | H11: =average(F11:G11) -> 1
A12: Process | B12: crit_10 | C12: structuration | D12: (feasib) Automated | E12: already tool-supported | F12: 2 | G12: 1 | H12: =average(F12:G12) -> 1.5
A13: Process | B13: crit_11 | C13: =C12 -> structuration | D13: (feasib) Deterministic | E13: same logic every time | F13: 3 | G13: 1 | H13: =average(F13:G13) -> 2
A14: Process | B14: crit_12 | C14: =C12 -> structuration | D14: (feasib) Documented | E14: existing methodology | F14: 1 | G14: 0 | H14: =average(F14:G14) -> 0.5
A15: Process | B15: crit_13 | C15: input | D15: (feasib) Structured data | E15: data already structured | F15: 3 | G15: 1 | H15: =average(F15:G15) -> 2
A16: Process | B16: crit_14 | C16: =C15 -> input | D16: (feasib) Fresh data | E16: data remain fresh along the time | F16: 3 | G16: 1 | H16: =average(F16:G16) -> 2

Sheet _scoring_reco
A1: [UUID- PK] | B1: [text] | C1: [text] | D1: [number] | E1: [number] | F1: [number] | G1: [number]
A2: id_reco | B2: recommendation | C2: description | D2: value_min | E2: value_max | F2: feasibility_min | G2: feasibility_max
A3: reco_01 | B3: 🎯 Priority 1 | C3: (value: high / feasibility: high) Process compatible & valuable for AI-powered workflow | D3: 1,5 | E3: 2,0 | F3: 1,5 | G3: 2,0
A4: reco_02 | B4: 🏃‍➡️ Quick win | C4: (value: low / feasibility: high) Process compatible for AI-powered workflow -> Assumption: foster AI-culture with quick deployment even on lower-value processes vs months for higher-value ones | D4: 1,0 | E4: 1,499 | F4: 1,5 | G4: 2,0
A5: reco_03 | B5: 🛠️ Prepare first | C5: (value: high / feasibility: low) Process/Data to first be restructured for AI-compliance | D5: 1,5 | E5: 2,0 | F5: 1,0 | G5: 1,499
A6: reco_04 | B6: ⏸️ Postpone | C6: (value: low / feasibility: low) Use only generic AI assistant/chatbot | D6: 1,0 | E6: 1,499 | F6: 1,0 | G6: 1,499

Sheet _settings_api
A1: [UUID- PK] | B1: [formula] | C1: [text] | D1: [text] | E1: [text] | F1: [text] | G1: [text] | H1: [text] | I1: [text] | J1: [text] | K1: [text] | L1: [text] | M1: [text] | N1: [text] | O1: [text] | P1: [text] | Q1: [date] | R1: [date]
A2: api_id | B2: api_label | C2: provider | D2: description | E2: end_Point | F2: auth_Type | G2: format_Input | H2: format_Output | I2: rate_Limit | J2: response_mapping | K2: handling_error | L2: handling_rateLimit | M2: ai_model | N2: ai_temperature | O2: ai_max_tokens | P2: is_active | Q2: created_at | R2: modified_at
A3: api_001 | B3: =C3&"-"&M3 -> OpenAI-GPT5.4 | C3: OpenAI | D3: Text Generation | E3: https://api.openai.com/v1/chat/completions | F3: API Key | G3: Prompt | H3: JSON | I3: 60/min | J3: {"content":"$.response.text","confidence":"$.response.score"} | K3: {"retryCount":3,"fallback":"manual_entry"} | L3: {"waitPeriod":60,"maxRetries":5} | M3: GPT5.4 | P3: TRUE
A4: api_002 | B4: =C4&"-"&M4 -> Anthropic-Opus 4.6 | C4: Anthropic | D4: Text Generation | E4: https://api.anthropic.com/v1/messages | F4: API Key | G4: Prompt | H4: JSON | I4: 60/min | J4: {"content":"$.completion","metaData":"$.stop_reason"} | K4: {"retryCount":3,"fallback":"skip"} | L4: {"waitPeriod":120,"maxRetries":3} | M4: Opus 4.6 | P4: FALSE
A5: api_003 | B5: =C5&"-"&M5 -> Mistral- | C5: Mistral | D5: Text Generation | E5: https://api.mistral.ai/v1/chat/completions | F5: API Key | G5: Prompt | H5: JSON | I5: 60/min | J5: {"content":"$.choices[0].message.content","model":"$.model"} | K5: {"retryCount":2,"fallback":"alternative_model"} | L5: {"waitPeriod":90,"maxRetries":3} | P5: FALSE
A6: api_004 | B6: =C6&"-"&M6 -> Linkedin- | C6: Linkedin | D6: Social Networking | E6: https://api.linkedin.com/v2/ | F6: OAuth 2.0 | G6: JSON | H6: JSON | I6: 100/hour | J6: {"profiles":"$.elements","total":"$.paging.total"} | K6: {"retryCount":1,"fallback":"cache"} | L6: {"waitPeriod":3600,"maxRetries":2} | P6: FALSE
A7: api_005 | B7: =C7&"-"&M7 -> Google Mail- | C7: Google Mail | D7: Email Management | E7: https://gmail.googleapis.com/gmail/v1/ | F7: OAuth 2.0 | G7: JSON | H7: JSON | I7: 250/day | J7: {"messages":"$.messages","nextPageToken":"$.nextPageToken"} | K7: {"retryCount":2,"fallback":"notify_user"} | L7: {"waitPeriod":300,"maxRetries":3} | P7: FALSE
A8: api_006 | B8: =C8&"-"&M8 -> Google Docs- | C8: Google Docs | D8: Document creation | E8: https://docs.googleapis.com/v1/documents | F8: OAuth 2.0 | G8: JSON | H8: JSON | I8: 300/min | J8: {"content":"$.body.content","title":"$.title"} | K8: {"retryCount":3,"fallback":"local_save"} | L8: {"waitPeriod":60,"maxRetries":5} | P8: FALSE
A9: api_007 | B9: =C9&"-"&M9 -> Google Slides- | C9: Google Slides | D9: Slides creation | E9: https://slides.googleapis.com/v1/presentations | F9: OAuth 2.0 | G9: JSON | H9: JSON | I9: 300/min | J9: {"slides":"$.slides","title":"$.title"} | K9: {"retryCount":3,"fallback":"local_save"} | L9: {"waitPeriod":60,"maxRetries":5} | P9: FALSE
A10: api_008 | B10: =C10&"-"&M10 -> Google Calendar- | C10: Google Calendar | D10: Calendar management | E10: https://www.googleapis.com/calendar/v3/ | F10: OAuth 2.0 | G10: JSON | H10: JSON | I10: 1000/day | J10: {"events":"$.items","nextToken":"$.nextPageToken"} | K10: {"retryCount":2,"fallback":"notify_user"} | L10: {"waitPeriod":120,"maxRetries":3} | P10: FALSE
A11: api_009 | B11: =C11&"-"&M11 -> Google Form- | C11: Google Form | D11: Form Management | E11: https://forms.googleapis.com/v1/forms | F11: OAuth 2.0 | G11: JSON | H11: JSON | I11: 500/day | J11: {"formId":"$.formId","items":"$.items"} | K11: {"retryCount":2,"fallback":"manual_retry"} | L11: {"waitPeriod":180,"maxRetries":3} | P11: FALSE
A12: api_010 | B12: =C12&"-"&M12 -> Canvas- | C12: Canvas | D12: Design | E12: https://api.canva.com/v1/templates | F12: API Key | G12: Design ID | H12: JSON | I12: 100/min | J12: {"templateUrl":"$.url","previewImage":"$.thumbnail"} | K12: {"retryCount":2,"fallback":"default_template"} | L12: {"waitPeriod":120,"maxRetries":4} | P12: FALSE
A13: api_011 | B13: =C13&"-"&M13 -> N8N- | C13: N8N | D13: Workflow automation | E13: https://[your-n8n-instance]/api/v1 | F13: API Key | G13: JSON | H13: JSON | J13: {"workflows":"$.data.workflows","totalCount":"$.data.totalCount"} {"executions":"$.data.executions","count":"$.data.count","nextCursor":"$.data.nextCursor"} | K13: {"retryCount":3,"fallback":"manual_retry"} | L13: {"waitPeriod":60,"maxRetries":3} | P13: FALSE

Sheet _settings_outputs
A1: [UUID- PK] | B1: [text] | C1: [text] | D1: [text] | E1: [text] | F1: [text] | G1: [datalist] | H1: [date] | I1: [date]
A2: id_output_config | B2: output | C2: prompt_report_system | D2: prompt_report_template | E2: 🚧 json_template | F2: output_folder_id | G2: default_language | H2: created_at | I2: modified_at
A3: rep_001 | B3: mission_report | C3: '- ROLE: You are an AI strategy consultant. - GOAL: Produce a structured report for the selected company and mission. --- | D3: CONTEXT {{COMPANY_CONTEXT}} --- MISSION {{MISSION_CONTEXT}} --- DATA {{MISSION_JSON}} --- EXPECTED OUTPUT 1. Executive summary 2. Strategic risks from AI 3. Priority opportunities 4. Priority processes 5. Recommended roadmap 6. Key watchouts | E3: { company: { id: "...", name: "...", country: "...", sector: "...", subSector: "...", offerType: "...", clientType: "...", description: "..." }, mission: { id: "...", name: "...", description: "...", priority: { strategy: ..., revenue: ..., cost: ..., implementation: ... } }, diagnosis: { strategy: [...], processes: [...], steps: [...] } } | G3: French

Sheet _options_list
A1: [UUID- PK] | B1: [text] | C1: [text]
A2: id_option | B2: title_option | C2: {=IFERROR("option_"&SEQUENCE(1,LOOKUP(2,1/(MMULT(TRANSPOSE(--(C3:AAA999<>"")),SEQUENCE(ROWS(C3:AAA999),1,1,0))>0),TRANSPOSE(COLUMN(C3:AAA3)))-COLUMN(C3)+1),"")} -> option_1 | D2: option_2 | E2: option_3 | F2: option_4 | G2: option_5 | H2: option_6 | I2: option_7 | J2: option_8 | K2: option_9 | L2: option_10 | M2: option_11 | N2: option_12 | O2: option_13 | P2: option_14 | Q2: option_15
A3: opt_001 | B3: scope_mission_type | C3: Strategy | D3: Process
A4: opt_002 | B4: scope_function | C4: #NA | D4: Strategy | E4: R&D | F4: Marketing | G4: Operations | H4: Sales & Service | I4: Finance | J4: HR | K4: IT/IS | L4: Communication | M4: Legal
A5: opt_003 | B5: country | C5: France | D5: US
A6: opt_004 | B6: sector | C6: Agriculture & Natural Resources | D6: Extraction & Raw Materials | E6: Manufacturing | F6: Construction & Infrastructure | G6: Energy & Utilities | H6: Transportation & Logistics | I6: Commerce & Distribution | J6: Hospitality, Tourism & Leisure | K6: Technology & Software | L6: Telecommunications & Digital Infrastructure | M6: Media & Content | N6: Professional & B2B Services | O6: Finance & Insurance | P6: Real Estate | Q6: Healthcare, Education & Personal Services
A7: opt_005 | B7: offer_type | C7: Extract raw material | D7: Make product | E7: Move / Sell product | F7: Serve | G7: Automate / Finance
A8: opt_006 | B8: client_type | C8: B2B | D8: B2C | E8: B2G
A9: opt_007 | B9: response_type | C9: Text | D9: Select
A10: opt_008 | B10: boolean | C10: TRUE | D10: FALSE
A11: opt_009 | B11: field_type | C11: [text] | D11: [number] | E11: [datalist] | F11: [date] | G11: [formula] | H11: [AI call] | I11: [UUID- PK] | J11: [UUID- FK] | K11: [gSheet-only helper]
A12: opt_010 | B12: status | C12: Draft | D12: Initialized | E12: Completed | F12: Reported

Sheet (🚧 WIP) reco_tool
A1: [text] | B1: [datalist] | C1: [datalist] | D1: [datalist] | E1: [datalist] | F1: [datalist] | G1: [datalist] | H1: [datalist] | I1: [datalist] | J1: [datalist] | K1: [datalist] | L1: [datalist] | M1: [datalist] | N1: [datalist] | O1: [datalist] | P1: [datalist] | Q1: [date] | R1: [date]
A2: CRITIERIA_TYPE | B2: value | C2: =B2 -> value | D2: =B2 -> value | E2: =B2 -> value | F2: activity_type | G2: =F2 -> activity_type | H2: =F2 -> activity_type | I2: =F2 -> activity_type | J2: skill | K2: =J2 -> skill | L2: structuration | M2: =L2 -> structuration | N2: =L2 -> structuration | O2: input | P2: =O2 -> input | Q2: created_at | R2: modified_at
A3: criteria_desc. | B3: process impact on revenues | C3: process impact on costs | D3: time consuming | E3: repeated | F3: crawl, query IS, contact stakeholders | G3: calculating/summarising, textual production | H3: creation of images / videos / audio | I3: discussion, orchestration tasks, multiple stakeholders | J3: requires intuition, craft, adaptability + manual gesture | K3: strong business-specific/contextual knowledge | L3: already tool-supported | M3: same logic every time | N3: existing methodology | O3: data already structured | P3: data remain fresh along the time
A4: criteria_title | B4: Revenue | C4: Cost | D4: FTE intensive | E4: Recurring | F4: Data collection | G4: Analysis & Writing | H4: Multimedia | I4: Interaction | J4: Human | K4: Business | L4: Automated | M4: Deterministic | N4: Documented | O4: Structured data | P4: Fresh data
A5: 🚧 reco_Chatbot | B5: 1 | C5: 1 | D5: 1 | E5: 1 | F5: 3 | G5: 3 | H5: 2 | I5: 3 | J5: 3 | K5: 3 | L5: 3 | M5: 3 | N5: 1 | O5: 3 | P5: 1
A6: 🚧 reco_Specific Tool | B6: 1 | C6: 1 | D6: 1 | E6: 1 | F6: 3 | G6: 2 | H6: 3 | I6: 1 | J6: 1 | K6: 1 | L6: 1 | M6: 1 | N6: 1 | O6: 1 | P6: 1
A7: 🚧 reco_Custom workflow | B7: 1 | C7: 1 | D7: 1 | E7: 1 | F7: 1 | G7: 1 | H7: 3 | I7: 3 | J7: 2 | K7: 3 | L7: 1 | M7: 1 | N7: 1 | O7: 1 | P7: 1
A8: 🚧 reco_AI Agent | B8: 1 | C8: 1 | D8: 1 | E8: 1 | F8: 1 | G8: 1 | H8: 3 | I8: 1 | J8: 1 | K8: 1 | L8: 1 | M8: 1 | N8: 1 | O8: 3 | P8: 3
